Workbook

Sheet 3차년도
A1: 4차년도 예산 | J1: 3차년도 이월금
B2: 직접비+간접비 | C2: 3100000000
A3: 1 | B3: 직접비 | C3: =C2*0.95 -> 2945000000 | F3: 현재까지 총액 | G3: =SUM(G5,G19,G57,G80,G94) -> 2526982800 | H3: =C3-G3 -> 418017200 | J3: 1 | K3: 직접비 | O3: 현재까지 총액 | P3: =SUM(P5,P15,P21,P43,P49) -> 50528180
A5: 1) | B5: 인건비 | G5: =SUM(G12,G17) -> 245648600 | J5: 1) | K5: 인건비 | P5: =P13 -> 30528180
B6: 구분 | C6: 성명 | D6: 직위 | E6: 월 급여 | F6: 참여기간(개월) | G6: 금액(원) | K6: 구분 | L6: 성명 | M6: 직위 | N6: 월 급여 | O6: 참여기간(개월) | P6: 금액(원)
B7: 행정전담인력 | C7: 강훈경 | D7: 행정원 | E7: 2450884 | F7: 10 | G7: =(E7*F7) -> 24508840 | H7: 이월금에서 3, 4월 분 지급 (협약 일정 항상 늦음) | K7: 행정전담인력 | L7: 강훈경 | M7: 행정원 | N7: 2450884 | O7: 2 | P7: =N7*O7 -> 4901768
C8: 한호철 | D8: 행정원 | E8: 4668777 | F8: 10 | G8: =E8*F8 -> 46687770 | H8: 21개월 약 420만원 | L8: 한호철 | M8: 행정원 | N8: 4668392 | O8: 2 | P8: =N8*O8 -> 9336784
C9: 권상미 | D9: 행정원 | E9: 4668777 | F9: 10 | G9: =E9*F9 -> 46687770 | H9: 18개월 약 360만원 | L9: 권상미 | M9: 행정원 | N9: 4668392 | O9: 2 | P9: =N9*O9 -> 9336784
C10: 양수림 | D10: 행정원 | E10: 3476422 | F10: 10 | G10: =E10*F10 -> 34764220 | L10: 고용예정 | M10: 행정원 | N10: 3476422 | O10: 2 | P10: =N10*O10 -> 6952844
C11: 소계 | G11: =SUM(G7:G10) -> 152648600 | L11: 소계 | P11: =SUM(P7:P10) -> 30528180
B12: 합계 | G12: =SUM(G11) -> 152648600
K13: 합계 | P13: =SUM(P11) -> 30528180
B14: 인센티브 | C14: (정부출연금의 3%이내)
B15: 구분 | C15: 산출내역 | G15: 금액(원) | J15: 2) | K15: 학생 인건비 | L15: =COUNT(#REF!,#REF!,#REF!) -> 0 | P15: 0
B16: 참여교수 및 직원 | G16: =C2*0.03 -> 93000000
B17: 합계 | G17: =G16 -> 93000000
A19: 2) | B19: 학생 인건비 | C19: =COUNT(G21:G44,#REF!,G46:G53) -> 32 | G19: =SUM(G55) -> 186600000
B20: 구분 | C20: 성명 | D20: 직위 | E20: 월 급여 | F20: 참여기간(개월) | G20: 금액(원)
B21: 교육 TA | C21: 김성주 | D21: 멘토 TA | E21: 900000 | F21: 8 | G21: =E21*F21 -> 7200000 | H21: 1학기, 2학기만. 인건비 확보 위해 10 --> 90 증액 | J21: 3) | K21: 연구시설장비비 | P21: =P26 -> 0
C22: 이찬 | D22: 장비 TA | E22: 900000 | F22: 6 | G22: =E22*F22 -> 5400000 | K22: 연구장비 구입 및 임차비
C23: 윤태현(이철호 교수님) | D23: 장비 TA | E23: 900000 | F23: 12 | G23: =E23*F23 -> 10800000 | K23: 품명 | L23: 용도 | M23: 단위 | N23: 수량 | O23: 단가(원) | P23: 현금(원)
C24: 최환히찬 | D24: 장비 TA | E24: 900000 | F24: 0 | G24: =E24*F24 -> 0 | H24: EDA tool (시높시스, 케이던스) 인수인계 기간 | K24: 첨단융합학부 | L24: GPU | N24: 0 | O24: 99990000 | P24: =N24*O24 -> 0 | Q24: 모자란 금액 (99,990,000 - 95,987,810)만큼 본예산 | R24: =99990000*1-P24 -> 99990000
C25: 최해찬 | D25: 장비 TA | E25: 900000 | F25: 0 | G25: =E25*F25 -> 0 | L25: Pulse Module | N25: 0 | O25: 62136800 | P25: =N25*O25 -> 0 | Q25: 납품 지연 --> 심의, 계약은 완료되었으므로 이월 가능
C26: 김영인 | D26: GPU 관리 TA | E26: 900000 | F26: 12 | G26: =E26*F26 -> 10800000 | K26: 합계 | P26: =SUM(P24:P25) -> 0
C27: 김진욱 | D27: GPU 관리 TA | E27: 900000 | F27: 12 | G27: =E27*F27 -> 10800000
C28: 황동호 | D28: 경진대회 TA | E28: 1300000 | F28: 0 | G28: =E28*F28 -> 0 | H28: 3차년도 교내경진대회 1달로 축소 (6월) | K28: 교육시설 설비 구축 및 개선
C29: 노혜리 | D29: 경진대회 TA | E29: 1300000 | F29: 0 | G29: =E29*F29 -> 0 | K29: 구분 | L29: 품명 | M29: 규격 | N29: 수량 | O29: 단가(원) | P29: 현금(원)
C30: 정제승 | D30: 첨융 칩 설계 TA | E30: 900000 | F30: 0 | G30: =E30*F30 -> 0 | H30: 3차년도 완료
C31: 김민선 | D31: 첨융 칩 설계 TA | E31: 900000 | F31: 0 | G31: =E31*F31 -> 0 | P31: =O31*N31 -> 0
C32: 고용예정 | D32: 특강 보조 TA | E32: 900000 | F32: 0 | G32: =E32*F32 -> 0 | H32: 9 ~ 12월 (추후 선발) | P32: =O32*N32 -> 0
C33: 고용예정 | D33: 특강 보조 TA | E33: 900000 | F33: 0 | G33: =E33*F33 -> 0 | P33: =O33*N33 -> 0
C34: 고용예정 | D34: 첨융 교육 TA (계절) | E34: 1200000 | F34: 6 | G34: =E34*F34 -> 7200000 | K34: 합계
C35: 고용예정 | D35: 첨융 교육 TA (계절) | E35: 1200000 | F35: 6 | G35: =E35*F35 -> 7200000
C36: 고용예정 | D36: 첨융 교육 TA (계절) | E36: 1200000 | F36: 6 | G36: =E36*F36 -> 7200000
C37: 고용예정 | D37: 첨융 교육 TA | E37: 900000 | F37: 8 | G37: =E37*F37 -> 7200000
C38: 고용예정 | D38: 첨융 교육 TA | E38: 900000 | F38: 8 | G38: =E38*F38 -> 7200000 | K38: 환경구축비
C39: 고용예정 | D39: 첨융 교육 TA | E39: 900000 | F39: 8 | G39: =E39*F39 -> 7200000 | K39: 구분 | L39: 산출내역 | P39: 금액(원)
C40: 고용예정 | D40: 첨융 교육 TA | E40: 900000 | F40: 8 | G40: =E40*F40 -> 7200000 | P40: =O40*N40 -> 0
C41: 고용예정 | D41: 첨융 교육 TA | E41: 900000 | F41: 8 | G41: =E41*F41 -> 7200000 | K41: 합계 | P41: =SUM(P40:P40) -> 0
C42: 고용예정 | D42: 첨융 교육 TA | E42: 900000 | F42: 8 | G42: =E42*F42 -> 7200000
...

Sheet 재정투자 계획 총괄표, 대응자금
A1: < 재정투자 계획 총괄표> (단위 : 백만원, %)
A2: 구 분 | B2: 정부출연금(A) | G2: 정부출연금(A) | H2: 평균 | I2: 민간투자지원*
H3: 비율 | M3: 교육운영비 동영상 인센티브 1400 반공연 공정실습 1200 기업협업교과목 1200
B4: 1차년도 | C4: 이월금 | D4: 2차년도 | E4: 이월금 | F4: 3차년도 | G4: 4차년도 | H4: (%) | I4: 현금 | J4: 현물 | K4: 소계
B5: (‘23.3～’24.2) | D5: (‘24.3～’25.2) | F5: (‘25.3～’26.2) | G5: (‘26.3～’27.2) | I5: (a) | J5: (b) | K5: (a+b)
A6: 직접비 | B6: 4142 | C6: 1169.9 | D6: 3808.79 | E6: 485.69 | F6: ='3차년도'!C3/1000000 -> 2945 | G6: ='3차년도'!C3/1000000 -> 2945 | H6: =(SUM(B6,D6,F6,G6) / $C$17)*100 -> 97.823531 | J6: -
A7: 인건비 | B7: 223.5 | C7: 44.9 | D7: 209.73 | E7: 4.03 | F7: ='3차년도'!G5/1000000 -> 245.6486 | G7: ='3차년도'!G5/1000000 -> 245.6486 | H7: =(SUM(B7,D7,F7,G7) / $C$17)*100 -> 6.5343463 | J7: -
A8: 학생인건비 | B8: 210.8 | C8: 0 | D8: 248.2 | E8: 0 | F8: ='3차년도'!G19/1000000 -> 186.6 | G8: ='3차년도'!G19/1000000 -> 186.6 | H8: =(SUM(B8,D8,F8,G8) / $C$17)*100 -> 5.8817988 | J8: -
A9: 연구시설·장비비 | B9: 2134.71 | C9: 329 | D9: 2611.8 | E9: 282.4 | F9: ='3차년도'!G57/1000000 -> 0 | G9: ='3차년도'!H3/1000000 -> 418.0172 | H9: =(SUM(B9,D9,F9,G9) / $C$17)*100 -> 36.501694 | J9: -
A10: 연구재료비 | B10: 168.86 | C10: 21.5 | D10: 19.19 | E10: 1.14 | F10: ='3차년도'!G80/1000000 -> 100 | G10: ='3차년도'!G80/1000000 -> 100 | H10: =(SUM(B10,D10,F10,G10) / $C$17)*100 -> 2.7426484 | J10: - | O10: 4.91
A11: 연구활동비 | B11: 1404.13 | C11: 774.5 | D11: 719.87 | E11: 198.12 | F11: ='3차년도'!G94/1000000 -> 1994.7342 | G11: ='3차년도'!G94/1000000 -> 1994.7342 | H11: =(SUM(B11,D11,F11,G11) / $C$17)*100 -> 43.208593 | J11: - | O11: 6.48
A12: 소계 | B12: 4142 | C12: 1169.9 | D12: =SUM(D7:D11) -> 3808.79 | E12: =SUM(E7:E11) -> 485.69 | F12: =SUM(F7:F11) -> 2526.9828 | G12: =SUM(G7:G11) -> 2945 | H12: =SUM(H7:H11) -> 94.869081 | J12: - | O12: 49.97
A13: 간접비 | B13: 218 | C13: 0 | D13: 200.46 | E13: 0 | F13: 152.5 | G13: ='3차년도'!C188/1000000 -> 155 | H13: =(SUM(B13,D13,F13,G13) / $C$17)*100 -> 5.1309189 | J13: - | O13: 3.06
A14: 소계 | B14: 218 | C14: 0 | D14: 200.46 | E14: 0 | F14: 152.5 | G14: =G13 -> 155 | H14: =SUM(H13) -> 5.1309189 | J14: - | O14: 30.58
A15: 합 계 | B15: 4360 | C15: 1169.9 | D15: =SUM(D12,D14) -> 4009.25 | E15: =SUM(E12,E14) -> 485.69 | F15: =SUM(F12,F14) -> 2679.4828 | G15: =SUM(G12,G14) -> 3100 | H15: =SUM(H12,H14) -> 100 | J15: -
A16: *이월금 포함
A17: 합계 총합 | C17: =SUM(B15,D15,F15,G15) -> 14148.733
A20: 구분 | C20: 삼성전자 | D20: sk하이닉스
A22: 인센티브 | C22: 4000000 | D22: 7000000 | E22: =SUM(C22:D22) -> 11000000 | G22: =SUM(C22:D28) -> 104005000 | H22: =SUM(G22,E29) -> 112630000
A23: 연구시설장비비 | C23: 3800000 | E23: =SUM(C23:D23) -> 3800000
A24: 연구활동비 | B24: 교육 운영비 | C24: 39000000 | E24: =SUM(C24:D24) -> 39000000 | F24: =SUM(E24:E28) -> 89205000
E25: =SUM(C25:D25) -> 0
B26: 출장비 | C26: 5000000 | D26: 7875000 | E26: =SUM(C26:D26) -> 12875000
B27: 행사운영비 | C27: 1000000 | D27: =17000000+13330000 -> 30330000 | E27: =SUM(C27:D27) -> 31330000
B28: 회의비 | C28: 6000000 | E28: =SUM(C28:D28) -> 6000000
A29: 간접비 | C29: 3000000 | D29: 5625000 | E29: =SUM(C29:D29) -> 8625000
J30: =37500000-24171200 -> 13328800
A31: 합계 | C31: =SUM(C22:C29) -> 61800000 | D31: =SUM(D22:D29) -> 50830000
A32: 5000+1180(이월금) | C32: 61800000 | D32: =37500000+13330000 -> 50830000 | E32: 3750+1333(이월금)
C33: =C32-C31 -> 0 | D33: =D32-D31 -> 0
A36: 행사운영비: 엔지니어링하우스에서 간담회 할때 대관료 대응자금

Sheet 3차년도 사업비 편성 총괄표
A1: < 3차년도 사업비 편성 총괄표> (단위 : 백만원, %)
A2: 구 분 | C2: 정부출연금 | D2: 비율 | E2: 이월금 | F2: 민간투자지원*
D3: (%) | F3: 현금(a) | G3: 현물(b) | H3: 소계(a+b)
A4: 인건비 | B4: 직원 인건비 | C4: ='3차년도'!G12/1000000 -> 152.6486 | D4: =(C4/$C$27)*100 -> 5.6969427 | E4: 4.03 | F4: 0 | H4: 0
B5: 인센티브 | C5: ='3차년도'!G17/1000000 -> 93 | D5: =(C5/$C$27)*100 -> 3.4708191 | E5: 0 | F5: 10 | H5: 10
A6: 소계 | C6: =SUM(C4,C5) -> 245.6486 | D6: =SUM(D4:D5) -> 9.1677618 | E6: =SUM(E4:E5) -> 4.03 | F6: =SUM(F4:F5) -> 10 | H6: =SUM(H4:H5) -> 10
A7: 학생 인건비 | B7: 학생인건비 | C7: ='3차년도'!G55/1000000 -> 186.6 | D7: =(C7/$C$27)*100 -> 6.9640305 | E7: 0 | F7: 0 | H7: 0
A8: 소계 | C8: =SUM(C7) -> 186.6 | D8: =SUM(D7) -> 6.9640305 | E8: 0 | F8: 0 | H8: 0
A9: 연구시설 장비비 | B9: 연구장비 구입 및 임차비 | C9: ='3차년도'!G65/1000000 -> 0 | D9: =(C9/$C$27)*100 -> 0 | E9: 282.4 | F9: 0 | H9: 0
B10: 교육시설 설비 구축 및 개선 | C10: ='3차년도'!G73/1000000 -> 0 | D10: =(C10/$C$27)*100 -> 0 | E10: 0 | F10: 3 | H10: 3
A11: 연구 재료비 | B11: 재료비 | C11: ='3차년도'!G91/1000000 -> 100 | D11: =(C11/$C$27)*100 -> 3.7320635 | E11: 1.14 | F11: 0 | H11: 0
A12: 연구 활동비 | B12: 장학금 | C12: ='3차년도'!G104/1000000 -> 1317.1 | D12: =(C12/$C$27)*100 -> 49.155009 | E12: 0 | F12: 0 | H12: 0
B13: 출장비 | C13: ='3차년도'!G116/1000000 -> 2.284 | D13: =(C13/$C$27)*100 -> 0.085240331 | E13: 0 | F13: 12.88 | H13: 12.88
B14: 회의비 | C14: ='3차년도'!G121/1000000 -> 0.575 | D14: =(C14/$C$27)*100 -> 0.021459365 | E14: 0 | F14: 5 | H14: 5
B15: 연구인력 지원비 | C15: ='3차년도'!G139/1000000 -> 142.688 | D15: =(C15/$C$27)*100 -> 5.3252068 | E15: 0 | F15: 0 | H15: 0
B16: 연구활동 유지비 | C16: 0 | D16: =(C16/$C$27)*100 -> 0 | E16: 39.6 | F16: 0 | H16: 0
B17: 연구실 운영비 | C17: ='3차년도'!G146/1000000 -> 0.55 | D17: =(C17/$C$27)*100 -> 0.020526349 | E17: 0.61 | F17: 0 | H17: 0
B18: 문헌구입비 | C18: ='3차년도'!G151/1000000 -> 0.15 | D18: =(C18/$C$27)*100 -> 0.0055980953 | E18: 0 | F18: 0 | H18: 0
B19: 인쇄비 | C19: ='3차년도'!G159/1000000 -> 10.579 | D19: =(C19/$C$27)*100 -> 0.394815 | E19: 0.15 | F19: 0 | H19: 0
B20: 운영경비-공공요금 | C20: ='3차년도'!G165/1000000 -> 2.053 | D20: =(C20/$C$27)*100 -> 0.076619264 | E20: 0 | F20: 0 | H20: 0
B21: 소프트웨어 활용비 | C21: ='3차년도'!G178/1000000 -> 508.3952 | D21: =(C21/$C$27)*100 -> 18.973632 | E21: 157.76 | F21: 0 | H21: 0
B22: 행사운영비 | C22: ='3차년도'!G171/1000000 -> 3.43 | D22: =(C22/$C$27)*100 -> 0.12800978 | E22: 0 | F22: 18 | H22: 18
B23: 교육운영비 | C23: ='3차년도'!G185/1000000 -> 6.93 | D23: =(C23/$C$27)*100 -> 0.258632 | E23: 0 | F23: 38 | H23: 38
A24: 소계 | C24: =SUM(C9:C23) -> 2094.7342 | D24: =SUM(D9:D23) -> 78.176811 | E24: =SUM(E9:E23) -> 481.66 | F24: =SUM(F9:F23) -> 76.88 | H24: =SUM(H9:H23) -> 76.88
A25: 간접비 | C25: 152.5 | D25: =(C25/$C$27)*100 -> 5.6913969 | E25: 0 | F25: 8.62 | H25: 8.62
A26: 소계 | C26: 152.5 | D26: =SUM(D25) -> 5.6913969 | E26: 0 | F26: 8.62 | H26: 8.62
A27: 합 계 | C27: =SUM(C6,C8,C24,C26) -> 2679.4828 | D27: =SUM(D6,D8,D24,D26) -> 100 | E27: =SUM(E24,E26,E8,E6) -> 485.69 | F27: =SUM(F26,F24,F6,F8) -> 95.5 | H27: =SUM(H26,H24,H6,H8) -> 95.5
A28: *이월금 포함
A30: 구분 | C30: 삼성전자* | D30: SK 하이닉스
A31: 인센티브 | C31: 5000000 | D31: 7000000 | E31: =SUM(C31:D31) -> 12000000 | G31: =SUM(E31:E37) -> 88875000
A32: 연구시설장비비 | C32: 2000000 | D32: 0 | E32: =SUM(C32:D33) -> 2000000
A34: 연구활동비 | B34: 교육운영비 | C34: 40000000 | D34: 0 | E34: =SUM(C34:D34) -> 40000000 | F34: =SUM(E34:E37) -> 74875000
B35: 출장비 | C35: 4500000 | D35: 7875000 | E35: =SUM(C35:D35) -> 12375000
B36: 행사운영비 | C36: 1000000 | D36: 17000000 | E36: =SUM(C36:D36) -> 18000000
B37: 회의비 | C37: 4500000 | D37: 0 | E37: =SUM(C37:D37) -> 4500000
A38: 간접비 | C38: 3000000 | D38: 5625000 | E38: =SUM(C38:D38) -> 8625000
